Traceback (most recent call last):
  File "/home/runner/workspace/.pythonlibs/lib/python3.11/site-packages/pydantic/networks.py", line 419, in import_email_validator
    import email_validator
ModuleNotFoundError: No module named 'email_validator'

The above exception was the direct cause of the following exception:

Traceback (most recent call last):
  File "/home/runner/workspace/main.py", line 12, in <module>
    class Subscriber(BaseModel):
  File "/home/runner/workspace/.pythonlibs/lib/python3.11/site-packages/pydantic/_internal/_model_construction.py", line 224, in __new__
    complete_model_class(
  File "/home/runner/workspace/.pythonlibs/lib/python3.11/site-packages/pydantic/_internal/_model_construction.py", line 577, in complete_model_class
    schema = cls.__get_pydantic_core_schema__(cls, handler)
             ^^^^^^^^^^^^^^^^^^^^^^^^^^^^^^^^^^^^^^^^^^^^^^
  File "/home/runner/workspace/.pythonlibs/lib/python3.11/site-packages/pydantic/main.py", line 671, in __get_pydantic_core_schema__
    return handler(source)
           ^^^^^^^^^^^^^^^
  File "/home/runner/workspace/.pythonlibs/lib/python3.11/site-packages/pydantic/_internal/_schema_generation_shared.py", line 83, in __call__
    schema = self._handler(source_type)
             ^^^^^^^^^^^^^^^^^^^^^^^^^^
  File "/home/runner/workspace/.pythonlibs/lib/python3.11/site-packages/pydantic/_internal/_generate_schema.py", line 655, in generate_schema
    schema = self._generate_schema_inner(obj)
             ^^^^^^^^^^^^^^^^^^^^^^^^^^^^^^^^
  File "/home/runner/workspace/.pythonlibs/lib/python3.11/site-packages/pydantic/_internal/_generate_schema.py", line 924, in _generate_schema_inner
    return self._model_schema(obj)
           ^^^^^^^^^^^^^^^^^^^^^^^
  File "/home/runner/workspace/.pythonlibs/lib/python3.11/site-packages/pydantic/_internal/_generate_schema.py", line 739, in _model_schema
    {k: self._generate_md_field_schema(k, v, decorators) for k, v in fields.items()},
    ^^^^^^^^^^^^^^^^^^^^^^^^^^^^^^^^^^^^^^^^^^^^^^^^^^^^^^^^^^^^^^^^^^^^^^^^^^^^^^^^
  File "/home/runner/workspace/.pythonlibs/lib/python3.11/site-packages/pydantic/_internal/_generate_schema.py", line 739, in <dictcomp>
    {k: self._generate_md_field_schema(k, v, deco